Workbook
Name Ahorro_rng: Listas!$E$2:$E$200
Name Cuentas_rng: Listas!$G$2:$G$100
Name Fijo_rng: Listas!$C$2:$C$197
Name Ingreso_rng: Listas!$B$2:$B$200
Name Inversion_rng: Listas!$F$2:$F$200
Name Tipos_rng: Listas!$I$2:$I$6
Name Variable_rng: Listas!$D$2:$D$199

Sheet Movimientos
A1: Fecha | B1: Mes | C1: Tipo | D1: Subcategoría | E1: Concepto | F1: Cuenta | G1: Monto (€)
A2: 45901 | B2: =IF(A2="","",LOWER(TEXT(A2,"[$-es-ES]mmmm"))&" "&YEAR(A2)) -> septiembre 2025 | C2: Ingreso | D2: Nómina / Sueldo | E2: Sueldo mensual | F2: Cuenta principal | G2: 1771.56
A3: 45901 | B3: =IF(A3="","",LOWER(TEXT(A3,"[$-es-ES]mmmm"))&" "&YEAR(A3)) -> septiembre 2025 | C3: Gasto fijo | D3: Alquiler / Hipoteca | E3: Alquiler septiembre | F3: Cuenta principal | G3: -488.83
A4: 45902 | B4: =IF(A4="","",LOWER(TEXT(A4,"[$-es-ES]mmmm"))&" "&YEAR(A4)) -> septiembre 2025 | C4: Gasto fijo | D4: Factura Luz/Agua/Gas | F4: Cuenta principal | G4: -6.82
A5: 45903 | B5: =IF(A5="","",LOWER(TEXT(A5,"[$-es-ES]mmmm"))&" "&YEAR(A5)) -> septiembre 2025 | C5: Gasto fijo | D5: Internet / Móvil | F5: Cuenta principal | G5: -10
A6: 45903 | B6: =IF(A6="","",LOWER(TEXT(A6,"[$-es-ES]mmmm"))&" "&YEAR(A6)) -> septiembre 2025 | C6: Gasto fijo | D6: Suscripciones esenciales | E6: Crunchi | F6: Cuenta principal | G6: -3.25
A7: 45903 | B7: =IF(A7="","",LOWER(TEXT(A7,"[$-es-ES]mmmm"))&" "&YEAR(A7)) -> septiembre 2025 | C7: Gasto fijo | D7: Factura Luz/Agua/Gas | F7: Cuenta principal | G7: -6.41
A8: 45903 | B8: =IF(A8="","",LOWER(TEXT(A8,"[$-es-ES]mmmm"))&" "&YEAR(A8)) -> septiembre 2025 | C8: Gasto variable | D8: Suscripciones | E8: Uber | F8: Cuenta principal | G8: -4.99
A9: 45904 | B9: =IF(A9="","",LOWER(TEXT(A9,"[$-es-ES]mmmm"))&" "&YEAR(A9)) -> septiembre 2025 | C9: Gasto variable | D9: Compras | E9: Regalo Carlos | F9: Cuenta principal | G9: -11.45
A10: 45905 | B10: =IF(A10="","",LOWER(TEXT(A10,"[$-es-ES]mmmm"))&" "&YEAR(A10)) -> septiembre 2025 | C10: Gasto variable | D10: Ropa | E10: Corbata | F10: Cuenta principal | G10: -37.5
A11: 45905 | B11: =IF(A11="","",LOWER(TEXT(A11,"[$-es-ES]mmmm"))&" "&YEAR(A11)) -> septiembre 2025 | C11: Gasto variable | D11: Supermercado | F11: Cuenta principal | G11: -3.4
A12: 45907 | B12: =IF(A12="","",LOWER(TEXT(A12,"[$-es-ES]mmmm"))&" "&YEAR(A12)) -> septiembre 2025 | C12: Gasto variable | D12: Supermercado | F12: Cuenta principal | G12: -4.61
A13: 45908 | B13: =IF(A13="","",LOWER(TEXT(A13,"[$-es-ES]mmmm"))&" "&YEAR(A13)) -> septiembre 2025 | C13: Gasto variable | D13: Gasolina | F13: Cuenta principal | G13: -22.07
A14: 45908 | B14: =IF(A14="","",LOWER(TEXT(A14,"[$-es-ES]mmmm"))&" "&YEAR(A14)) -> septiembre 2025 | C14: Gasto fijo | D14: Gym | F14: Cuenta principal | G14: -29.99
A15: 45909 | B15: =IF(A15="","",LOWER(TEXT(A15,"[$-es-ES]mmmm"))&" "&YEAR(A15)) -> septiembre 2025 | C15: Gasto fijo | D15: Supermercado (básico) | F15: Cuenta principal | G15: -6.88
A16: 45909 | B16: =IF(A16="","",LOWER(TEXT(A16,"[$-es-ES]mmmm"))&" "&YEAR(A16)) -> septiembre 2025 | C16: Gasto fijo | D16: Farmacia | E16: Avidart | F16: Cuenta principal | G16: -20.11
A17: 45910 | B17: =IF(A17="","",LOWER(TEXT(A17,"[$-es-ES]mmmm"))&" "&YEAR(A17)) -> septiembre 2025 | C17: Gasto fijo | D17: Suscripciones esenciales | E17: Netflix | F17: Cuenta principal | G17: -6.99
A18: 45910 | B18: =IF(A18="","",LOWER(TEXT(A18,"[$-es-ES]mmmm"))&" "&YEAR(A18)) -> septiembre 2025 | C18: Gasto fijo | D18: Factura Luz/Agua/Gas | F18: Cuenta principal | G18: -15.66
A19: 45911 | B19: =IF(A19="","",LOWER(TEXT(A19,"[$-es-ES]mmmm"))&" "&YEAR(A19)) -> septiembre 2025 | C19: Gasto variable | D19: Donacion | F19: Cuenta principal | G19: -15
A20: 45911 | B20: =IF(A20="","",LOWER(TEXT(A20,"[$-es-ES]mmmm"))&" "&YEAR(A20)) -> septiembre 2025 | C20: Gasto fijo | D20: Supermercado (básico) | F20: Cuenta principal | G20: -77.04
A21: 45912 | B21: =IF(A21="","",LOWER(TEXT(A21,"[$-es-ES]mmmm"))&" "&YEAR(A21)) -> septiembre 2025 | C21: Gasto variable | D21: Restaurantes | F21: Cuenta principal | G21: -30.8
A22: 45914 | B22: =IF(A22="","",LOWER(TEXT(A22,"[$-es-ES]mmmm"))&" "&YEAR(A22)) -> septiembre 2025 | C22: Gasto variable | D22: Restaurantes | F22: Cuenta principal | G22: -54.18
A23: 45917 | B23: =IF(A23="","",LOWER(TEXT(A23,"[$-es-ES]mmmm"))&" "&YEAR(A23)) -> septiembre 2025 | C23: Gasto fijo | D23: Suscripciones esenciales | E23: OpenAI | F23: Cuenta principal | G23: -23
A24: 45917 | B24: =IF(A24="","",LOWER(TEXT(A24,"[$-es-ES]mmmm"))&" "&YEAR(A24)) -> septiembre 2025 | C24: Gasto variable | D24: Restaurantes | F24: Cuenta principal | G24: -5.99
A25: 45919 | B25: =IF(A25="","",LOWER(TEXT(A25,"[$-es-ES]mmmm"))&" "&YEAR(A25)) -> septiembre 2025 | C25: Gasto fijo | D25: Supermercado (básico) | F25: Cuenta principal | G25: -25.59
A26: 45920 | B26: =IF(A26="","",LOWER(TEXT(A26,"[$-es-ES]mmmm"))&" "&YEAR(A26)) -> septiembre 2025 | C26: Gasto variable | D26: Taxi / VTC | E26: Metro | F26: Cuenta principal | G26: -7.3
A27: 45920 | B27: =IF(A27="","",LOWER(TEXT(A27,"[$-es-ES]mmmm"))&" "&YEAR(A27)) -> septiembre 2025 | C27: Gasto variable | D27: Compras | E27: Regalo Marta | F27: Cuenta principal | G27: -12
A28: 45923 | B28: =IF(A28="","",LOWER(TEXT(A28,"[$-es-ES]mmmm"))&" "&YEAR(A28)) -> septiembre 2025 | C28: Gasto fijo | D28: Supermercado (básico) | F28: Cuenta principal | G28: -1.93
A29: 45924 | B29: =IF(A29="","",LOWER(TEXT(A29,"[$-es-ES]mmmm"))&" "&YEAR(A29)) -> septiembre 2025 | C29: Gasto fijo | D29: Supermercado (básico) | F29: Cuenta principal | G29: -21.69
A30: 45925 | B30: =IF(A30="","",LOWER(TEXT(A30,"[$-es-ES]mmmm"))&" "&YEAR(A30)) -> septiembre 2025 | C30: Gasto variable | D30: Compras | E30: Tarta | F30: Cuenta principal | G30: -12.5
A31: 45926 | B31: =IF(A31="","",LOWER(TEXT(A31,"[$-es-ES]mmmm"))&" "&YEAR(A31)) -> septiembre 2025 | C31: Gasto variable | D31: Taxi / VTC | F31: Cuenta principal | G31: -5.62
A32: 45926 | B32: =IF(A32="","",LOWER(TEXT(A32,"[$-es-ES]mmmm"))&" "&YEAR(A32)) -> septiembre 2025 | C32: Gasto variable | D32: Supermercado | F32: Cuenta principal | G32: -7.95
A33: 45927 | B33: =IF(A33="","",LOWER(TEXT(A33,"[$-es-ES]mmmm"))&" "&YEAR(A33)) -> septiembre 2025 | C33: Gasto variable | D33: Restaurantes | F33: Cuenta principal | G33: -25.14
A34: 45929 | B34: =IF(A34="","",LOWER(TEXT(A34,"[$-es-ES]mmmm"))&" "&YEAR(A34)) -> septiembre 2025 | C34: Gasto variable | D34: Supermercado | F34: Cuenta principal | G34: -1.59
A35: 45930 | B35: =IF(A35="","",LOWER(TEXT(A35,"[$-es-ES]mmmm"))&" "&YEAR(A35)) -> septiembre 2025 | C35: Gasto fijo | D35: Supermercado (básico) | F35: Cuenta principal | G35: -4
A36: 45930 | B36: =IF(A36="","",LOWER(TEXT(A36,"[$-es-ES]mmmm"))&" "&YEAR(A36)) -> septiembre 2025 | C36: Gasto variable | D36: Restaurantes | F36: Cuenta principal | G36: -4
A37: 45930 | B37: =IF(A37="","",LOWER(TEXT(A37,"[$-es-ES]mmmm"))&" "&YEAR(A37)) -> septiembre 2025 | C37: Ahorro | D37: Fondo de emergencia | F37: Cuenta principal | G37: -757.28
A38: 45931 | B38: =IF(A38="","",LOWER(TEXT(A38,"[$-es-ES]mmmm"))&" "&YEAR(A38)) -> octubre 2025 | C38: Ingreso | D38: Nómina / Sueldo | F38: Cuenta principal | G38: 2088
A39: 45931 | B39: =IF(A39="","",LOWER(TEXT(A39,"[$-es-ES]mmmm"))&" "&YEAR(A39)) -> octubre 2025 | C39: Ingreso | D39: Nómina / Sueldo | E39: Finiquito | F39: Cuenta principal | G39: 2230.81
A40: 45931 | B40: =IF(A40="","",LOWER(TEXT(A40,"[$-es-ES]mmmm"))&" "&YEAR(A40)) -> octubre 2025 | C40: Gasto fijo | D40: Alquiler / Hipoteca | F40: Cuenta principal | G40: -565.49
...

Sheet Panel_Mensual
A1: Mes seleccionado | B1: marzo 2026
A2: Categoría | B2: Presupuesto (€) | C2: Real (€) | D2: Disponible (€) | E2: % Cumplido | F2: Estado
A3: Fijos | B3: =Parametros!$B$1*Parametros!$B$4/100 -> 945 | C3: =-SUMIFS(Movimientos!$G:$G,Movimientos!$B:$B,$B$1,Movimientos!$C:$C,"Gasto fijo") -> 710.63 | D3: =B3-C3 -> 234.37 | E3: =IF(B3=0,0,C3/B3) -> 0.75198942 | F3: =IF(E3>1,"⚠ Sobrepasado","OK") -> OK
A4: Variables | B4: =Parametros!$B$1*Parametros!$B$5/100 -> 525 | C4: =-SUMIFS(Movimientos!$G:$G,Movimientos!$B:$B,$B$1,Movimientos!$C:$C,"Gasto variable") -> 72.33 | D4: =B4-C4 -> 452.67 | E4: =IF(B4=0,0,C4/B4) -> 0.13777143 | F4: =IF(E4>1,"⚠ Sobrepasado","OK") -> OK
A5: Ahorro | B5: =Parametros!$B$1*Parametros!$B$6/100 -> 315 | C5: =-SUMIFS(Movimientos!$G:$G,Movimientos!$B:$B,$B$1,Movimientos!$C:$C,"Ahorro") -> 0 | D5: =B5-C5 -> 315 | E5: =IF(B5=0,0,C5/B5) -> 0 | F5: =IF(E5>1,"⚠ Sobrepasado","OK") -> OK
A6: Inversión | B6: =Parametros!$B$1*Parametros!$B$7/100 -> 315 | C6: =-SUMIFS(Movimientos!$G:$G,Movimientos!$B:$B,$B$1,Movimientos!$C:$C,"Inversión") -> 0 | D6: =B6-C6 -> 315 | E6: =IF(B6=0,0,C6/B6) -> 0 | F6: =IF(E6>1,"⚠ Sobrepasado","OK") -> OK
A8: Ingresos (real) | C8: =SUMIFS(Movimientos!$G:$G,Movimientos!$B:$B,$B$1,Movimientos!$C:$C,"Ingreso") -> 2343.9
A9: Gastos (real) | C9: =C3+C4 -> 782.96
A10: Presupuesto total | C10: =B3+B4+B5+B6 -> 2100
A11: Cumplimiento total | C11: =IF(C10=0,0,C9/C10) -> 0.3728381
A12: Balance (real) | C12: =C8-C9 -> 1560.94
A20: Mes seleccionado | B20: septiembre 2025
A21: Categoría | B21: Presupuesto (€) | C21: Real (€) | D21: Disponible (€) | E21: % Cumplido | F21: Estado
A22: Fijos | B22: 797.202 | C22: 748.19 | D22: 49.012 | E22: 0.93851997 | F22: OK
A23: Variables | B23: 442.89 | C23: 266.09 | D23: 176.8 | E23: 0.60080381 | F23: OK
A24: Ahorro | B24: 265.734 | C24: 457.28 | D24: -191.546 | E24: 1.7208186 | F24: ⚠ Sobrepasado
A25: Inversión | B25: 265.734 | C25: 300 | D25: -34.266 | E25: 1.1289485 | F25: ⚠ Sobrepasado
A27: Ingresos (real) | C27: 1771.56
A28: Gastos (real) | C28: 1014.28
A29: Presupuesto total | C29: 1771.56
A30: Cumplimiento total | C30: 0.57253494
A31: Balance (real) | C31: 757.28

Sheet Dashboard
B1: DASHBOARD FINANCIERO
C3: Ingresos (real) | H3: Gastos (real) | M3: Presupuesto total | R3: Balance
C4: =Panel_Mensual!C8 -> 2343.9 | H4: =Panel_Mensual!C9 -> 782.96 | M4: =Panel_Mensual!C10 -> 2100 | R4: =Panel_Mensual!C12 -> 1560.94
C7: Fijos (real) | H7: Variables (real) | M7: Ahorro (real) | R7: Inversión (real)
C8: =Panel_Mensual!C3 -> 710.63 | H8: =Panel_Mensual!C4 -> 72.33 | M8: =Panel_Mensual!C5 -> 0 | R8: =Panel_Mensual!C6 -> 0
D11: Progreso por categoría
D12: Categoría | E12: % Cumplido | F12: Disponible (€) | G12: Estado
D13: Fijos | E13: =Panel_Mensual!E3 -> 0.75198942 | F13: =Panel_Mensual!D3 -> 234.37 | G13: =Panel_Mensual!F3 -> OK
D14: Variables | E14: =Panel_Mensual!E4 -> 0.13777143 | F14: =Panel_Mensual!D4 -> 452.67 | G14: =Panel_Mensual!F4 -> OK
D15: Ahorro | E15: =Panel_Mensual!E5 -> 0 | F15: =Panel_Mensual!D5 -> 315 | G15: =Panel_Mensual!F5 -> OK
D16: Inversión | E16: =Panel_Mensual!E6 -> 0 | F16: =Panel_Mensual!D6 -> 315 | G16: =Panel_Mensual!F6 -> OK

Sheet Resumen_12m
A1: Mes | B1: Gastos (€) | C1: Ingresos (€) | D1: Ahorro (€) | E1: Inversión (€)
A2: =Listas!A2 -> enero 2025 | B2: =-SUMIFS(Movimientos!$G:$G,Movimientos!$B:$B,A2,Movimientos!$C:$C,"Gasto fijo") - SUMIFS(Movimientos!$G:$G,Movimientos!$B:$B,A2,Movimientos!$C:$C,"Gasto variable") -> 0 | C2: =SUMIFS(Movimientos!$G:$G,Movimientos!$B:$B,A2,Movimientos!$C:$C,"Ingreso") -> 0 | D2: =-SUMIFS(Movimientos!$G:$G,Movimientos!$B:$B,A2,Movimientos!$C:$C,"Ahorro") -> 0 | E2: =-SUMIFS(Movimientos!$G:$G,Movimientos!$B:$B,A2,Movimientos!$C:$C,"Inversión") -> 0
A3: =Listas!A3 -> febrero 2025 | B3: =-SUMIFS(Movimientos!$G:$G,Movimientos!$B:$B,A3,Movimientos!$C:$C,"Gasto fijo") - SUMIFS(Movimientos!$G:$G,Movimientos!$B:$B,A3,Movimientos!$C:$C,"Gasto variable") -> 0 | C3: =SUMIFS(Movimientos!$G:$G,Movimientos!$B:$B,A3,Movimientos!$C:$C,"Ingreso") -> 0 | D3: =-SUMIFS(Movimientos!$G:$G,Movimientos!$B:$B,A3,Movimientos!$C:$C,"Ahorro") -> 0 | E3: =-SUMIFS(Movimientos!$G:$G,Movimientos!$B:$B,A3,Movimientos!$C:$C,"Inversión") -> 0
A4: =Listas!A4 -> marzo 2025 | B4: =-SUMIFS(Movimientos!$G:$G,Movimientos!$B:$B,A4,Movimientos!$C:$C,"Gasto fijo") - SUMIFS(Movimientos!$G:$G,Movimientos!$B:$B,A4,Movimientos!$C:$C,"Gasto variable") -> 0 | C4: =SUMIFS(Movimientos!$G:$G,Movimientos!$B:$B,A4,Movimientos!$C:$C,"Ingreso") -> 0 | D4: =-SUMIFS(Movimientos!$G:$G,Movimientos!$B:$B,A4,Movimientos!$C:$C,"Ahorro") -> 0 | E4: =-SUMIFS(Movimientos!$G:$G,Movimientos!$B:$B,A4,Movimientos!$C:$C,"Inversión") -> 0
A5: =Listas!A5 -> abril 2025 | B5: =-SUMIFS(Movimientos!$G:$G,Movimientos!$B:$B,A5,Movimientos!$C:$C,"Gasto fijo") - SUMIFS(Movimientos!$G:$G,Movimientos!$B:$B,A5,Movimientos!$C:$C,"Gasto variable") -> 0 | C5: =SUMIFS(Movimientos!$G:$G,Movimientos!$B:$B,A5,Movimientos!$C:$C,"Ingreso") -> 0 | D5: =-SUMIFS(Movimientos!$G:$G,Movimientos!$B:$B,A5,Movimientos!$C:$C,"Ahorro") -> 0 | E5: =-SUMIFS(Movimientos!$G:$G,Movimientos!$B:$B,A5,Movimientos!$C:$C,"Inversión") -> 0
A6: =Listas!A6 -> mayo 2025 | B6: =-SUMIFS(Movimientos!$G:$G,Movimientos!$B:$B,A6,Movimientos!$C:$C,"Gasto fijo") - SUMIFS(Movimientos!$G:$G,Movimientos!$B:$B,A6,Movimientos!$C:$C,"Gasto variable") -> 0 | C6: =SUMIFS(Movimientos!$G:$G,Movimientos!$B:$B,A6,Movimientos!$C:$C,"Ingreso") -> 0 | D6: =-SUMIFS(Movimientos!$G:$G,Movimientos!$B:$B,A6,Movimientos!$C:$C,"Ahorro") -> 0 | E6: =-SUMIFS(Movimientos!$G:$G,Movimientos!$B:$B,A6,Movimientos!$C:$C,"Inversión") -> 0
A7: =Listas!A7 -> junio 2025 | B7: =-SUMIFS(Movimientos!$G:$G,Movimientos!$B:$B,A7,Movimientos!$C:$C,"Gasto fijo") - SUMIFS(Movimientos!$G:$G,Movimientos!$B:$B,A7,Movimientos!$C:$C,"Gasto variable") -> 0 | C7: =SUMIFS(Movimientos!$G:$G,Movimientos!$B:$B,A7,Movimientos!$C:$C,"Ingreso") -> 0 | D7: =-SUMIFS(Movimientos!$G:$G,Movimientos!$B:$B,A7,Movimientos!$C:$C,"Ahorro") -> 0 | E7: =-SUMIFS(Movimientos!$G:$G,Movimientos!$B:$B,A7,Movimientos!$C:$C,"Inversión") -> 0
A8: =Listas!A8 -> julio 2025 | B8: =-SUMIFS(Movimientos!$G:$G,Movimientos!$B:$B,A8,Movimientos!$C:$C,"Gasto fijo") - SUMIFS(Movimientos!$G:$G,Movimientos!$B:$B,A8,Movimientos!$C:$C,"Gasto variable") -> 0 | C8: =SUMIFS(Movimientos!$G:$G,Movimientos!$B:$B,A8,Movimientos!$C:$C,"Ingreso") -> 0 | D8: =-SUMIFS(Movimientos!$G:$G,Movimientos!$B:$B,A8,Movimientos!$C:$C,"Ahorro") -> 0 | E8: =-SUMIFS(Movimientos!$G:$G,Movimientos!$B:$B,A8,Movimientos!$C:$C,"Inversión") -> 0
A9: =Listas!A9 -> agosto 2025 | B9: =-SUMIFS(Movimientos!$G:$G,Movimientos!$B:$B,A9,Movimientos!$C:$C,"Gasto fijo") - SUMIFS(Movimientos!$G:$G,Movimientos!$B:$B,A9,Movimientos!$C:$C,"Gasto variable") -> 0 | C9: =SUMIFS(Movimientos!$G:$G,Movimientos!$B:$B,A9,Movimientos!$C:$C,"Ingreso") -> 0 | D9: =-SUMIFS(Movimientos!$G:$G,Movimientos!$B:$B,A9,Movimientos!$C:$C,"Ahorro") -> 0 | E9: =-SUMIFS(Movimientos!$G:$G,Movimientos!$B:$B,A9,Movimientos!$C:$C,"Inversión") -> 0
A10: =Listas!A10 -> septiembre 2025 | B10: =-SUMIFS(Movimientos!$G:$G,Movimientos!$B:$B,A10,Movimientos!$C:$C,"Gasto fijo") - SUMIFS(Movimientos!$G:$G,Movimientos!$B:$B,A10,Movimientos!$C:$C,"Gasto variable") -> 1014.28 | C10: =SUMIFS(Movimientos!$G:$G,Movimientos!$B:$B,A10,Movimientos!$C:$C,"Ingreso") -> 1771.56 | D10: =-SUMIFS(Movimientos!$G:$G,Movimientos!$B:$B,A10,Movimientos!$C:$C,"Ahorro") -> 757.28 | E10: =-SUMIFS(Movimientos!$G:$G,Movimientos!$B:$B,A10,Movimientos!$C:$C,"Inversión") -> 0
A11: =Listas!A11 -> octubre 2025 | B11: =-SUMIFS(Movimientos!$G:$G,Movimientos!$B:$B,A11,Movimientos!$C:$C,"Gasto fijo") - SUMIFS(Movimientos!$G:$G,Movimientos!$B:$B,A11,Movimientos!$C:$C,"Gasto variable") -> 1433.58 | C11: =SUMIFS(Movimientos!$G:$G,Movimientos!$B:$B,A11,Movimientos!$C:$C,"Ingreso") -> 5371.95 | D11: =-SUMIFS(Movimientos!$G:$G,Movimientos!$B:$B,A11,Movimientos!$C:$C,"Ahorro") -> 3938.37 | E11: =-SUMIFS(Movimientos!$G:$G,Movimientos!$B:$B,A11,Movimientos!$C:$C,"Inversión") -> 0
A12: =Listas!A12 -> noviembre 2025 | B12: =-SUMIFS(Movimientos!$G:$G,Movimientos!$B:$B,A12,Movimientos!$C:$C,"Gasto fijo") - SUMIFS(Movimientos!$G:$G,Movimientos!$B:$B,A12,Movimientos!$C:$C,"Gasto variable") -> 1279.95 | C12: =SUMIFS(Movimientos!$G:$G,Movimientos!$B:$B,A12,Movimientos!$C:$C,"Ingreso") -> 2186.03 | D12: =-SUMIFS(Movimientos!$G:$G,Movimientos!$B:$B,A12,Movimientos!$C:$C,"Ahorro") -> 906.08 | E12: =-SUMIFS(Movimientos!$G:$G,Movimientos!$B:$B,A12,Movimientos!$C:$C,"Inversión") -> 0
A13: =Listas!A13 -> diciembre 2025 | B13: =-SUMIFS(Movimientos!$G:$G,Movimientos!$B:$B,A13,Movimientos!$C:$C,"Gasto fijo") - SUMIFS(Movimientos!$G:$G,Movimientos!$B:$B,A13,Movimientos!$C:$C,"Gasto variable") -> 2582.02 | C13: =SUMIFS(Movimientos!$G:$G,Movimientos!$B:$B,A13,Movimientos!$C:$C,"Ingreso") -> 4910.84 | D13: =-SUMIFS(Movimientos!$G:$G,Movimientos!$B:$B,A13,Movimientos!$C:$C,"Ahorro") -> 2328.82 | E13: =-SUMIFS(Movimientos!$G:$G,Movimientos!$B:$B,A13,Movimientos!$C:$C,"Inversión") -> 0
... A21: =Listas!A21 -> agosto 2026 | B21: =-SUMIFS(Movimientos!$G:$G,Movimientos!$B:$B,A21,Movimientos!$C:$C,"Gasto fijo") - SUMIFS(Movimientos!$G:$G,Movimientos!$B:$B,A21,Movimientos!$C:$C,"Gasto variable") -> 0 | C21: =SUMIFS(Movimientos!$G:$G,Movimientos!$B:$B,A21,Movimientos!$C:$C,"Ingreso") -> 0 | D21: =-SUMIFS(Movimientos!$G:$G,Movimientos!$B:$B,A21,Movimientos!$C:$C,"Ahorro") -> 0 | E21: =-SUMIFS(Movimientos!$G:$G,Movimientos!$B:$B,A21,Movimientos!$C:$C,"Inversión") -> 0
A22: =Listas!A22 -> septiembre 2026 | B22: =-SUMIFS(Movimientos!$G:$G,Movimientos!$B:$B,A22,Movimientos!$C:$C,"Gasto fijo") - SUMIFS(Movimientos!$G:$G,Movimientos!$B:$B,A22,Movimientos!$C:$C,"Gasto variable") -> 0 | C22: =SUMIFS(Movimientos!$G:$G,Movimientos!$B:$B,A22,Movimientos!$C:$C,"Ingreso") -> 0 | D22: =-SUMIFS(Movimientos!$G:$G,Movimientos!$B:$B,A22,Movimientos!$C:$C,"Ahorro") -> 0 | E22: =-SUMIFS(Movimientos!$G:$G,Movimientos!$B:$B,A22,Movimientos!$C:$C,"Inversión") -> 0 | H22: Año | I22: Gastos (€) | J22: Ingresos (€) | K22: Ahorro (€)
A23: =Listas!A23 -> octubre 2026 | B23: =-SUMIFS(Movimientos!$G:$G,Movimientos!$B:$B,A23,Movimientos!$C:$C,"Gasto fijo") - SUMIFS(Movimientos!$G:$G,Movimientos!$B:$B,A23,Movimientos!$C:$C,"Gasto variable") -> 0 | C23: =SUMIFS(Movimientos!$G:$G,Movimientos!$B:$B,A23,Movimientos!$C:$C,"Ingreso") -> 0 | D23: =-SUMIFS(Movimientos!$G:$G,Movimientos!$B:$B,A23,Movimientos!$C:$C,"Ahorro") -> 0 | E23: =-SUMIFS(Movimientos!$G:$G,Movimientos!$B:$B,A23,Movimientos!$C:$C,"Inversión") -> 0 | H23: 2025 | I23: =SUM(B2:B13) -> 6309.83 | J23: =SUM(C2:C13) -> 14240.38 | K23: =SUM(D2:D13) -> 7930.55
A24: =Listas!A24 -> noviembre 2026 | B24: =-SUMIFS(Movimientos!$G:$G,Movimientos!$B:$B,A24,Movimientos!$C:$C,"Gasto fijo") - SUMIFS(Movimientos!$G:$G,Movimientos!$B:$B,A24,Movimientos!$C:$C,"Gasto variable") -> 0 | C24: =SUMIFS(Movimientos!$G:$G,Movimientos!$B:$B,A24,Movimientos!$C:$C,"Ingreso") -> 0 | D24: =-SUMIFS(Movimientos!$G:$G,Movimientos!$B:$B,A24,Movimientos!$C:$C,"Ahorro") -> 0 | E24: =-SUMIFS(Movimientos!$G:$G,Movimientos!$B:$B,A24,Movimientos!$C:$C,"Inversión") -> 0 | H24: 2026 | I24: =SUM(B14:B25) -> 3742.27 | J24: =SUM(C14:C25) -> 7537.8 | K24: =SUM(D14:D25) -> 2234.59
A25: =Listas!A25 -> diciembre 2026 | B25: =-SUMIFS(Movimientos!$G:$G,Movimientos!$B:$B,A25,Movimientos!$C:$C,"Gasto fijo") - SUMIFS(Movimientos!$G:$G,Movimientos!$B:$B,A25,Movimientos!$C:$C,"Gasto variable") -> 0 | C25: =SUMIFS(Movimientos!$G:$G,Movimientos!$B:$B,A25,Movimientos!$C:$C,"Ingreso") -> 0 | D25: =-SUMIFS(Movimientos!$G:$G,Movimientos!$B:$B,A25,Movimientos!$C:$C,"Ahorro") -> 0 | E25: =-SUMIFS(Movimientos!$G:$G,Movimientos!$B:$B,A25,Movimientos!$C:$C,"Inversión") -> 0

Sheet Parametros
A1: Ingreso planificado mensual (€) | B1: 2100
A3: Categoría | B3: Porcentaje (%) | C3: Planificado (€) | D3: Vista rápida
A4: Fijos | B4: 45 | C4: =$B$1*B4/100 -> 945 | D4: =TEXT(B4/100,"0%")&" · "&TEXT(C4,"#,##0.00 €") -> 45% · 945,000 €
A5: Variables | B5: 25 | C5: =$B$1*B5/100 -> 525 | D5: =TEXT(B5/100,"0%")&" · "&TEXT(C5,"#,##0.00 €") -> 25% · 525,000 €
A6: Ahorro | B6: 15 | C6: =$B$1*B6/100 -> 315 | D6: =TEXT(B6/100,"0%")&" · "&TEXT(C6,"#,##0.00 €") -> 15% · 315,000 €
A7: Inversión | B7: 15 | C7: =$B$1*B7/100 -> 315 | D7: =TEXT(B7/100,"0%")&" · "&TEXT(C7,"#,##0.00 €") -> 15% · 315,000 €

Sheet Listas
A1: Meses | B1: Ingreso | C1: Gasto fijo | D1: Gasto variable | E1: Ahorro | F1: Inversión | G1: Cuentas | H1: Mes_nombres | I1: Tipos
A2: enero 2025 | B2: Sueldo | C2: Alquiler / Hipoteca | D2: Restaurantes | E2: Fondo de emergencia | F2: Indexado global | G2: Cuenta principal | H2: enero | I2: Ingreso
A3: febrero 2025 | B3: Intereses / Dividendos | C3: Luz | D3: Ocio | E3: Meta corto plazo | F3: Acciones / ETFs | G3: Cuenta comun | H3: febrero | I3: Gasto fijo
A4: marzo 2025 | B4: Devolución impuestos | C4: Agua | D4: Viajes | E4: Meta coche | F4: Renta fija | G4: Tarjeta débito | H4: marzo | I4: Gasto variable
A5: abril 2025 | B5: Regalos recibidos | C5: Gas | D5: Ropa | E5: Meta estudios | F5: Plan de pensiones | G5: Cuenta ahorro | H5: abril | I5: Ahorro
A6: mayo 2025 | B6: Otros ingresos | C6: Internet / Móvil | D6: Compras | E6: Meta viaje | F6: Fondo mixto | G6: Broker | H6: mayo | I6: Inversión
A7: junio 2025 | C7: Supermercado (básico) | D7: Transporte | F7: Crypto | H7: junio
A8: julio 2025 | C8: Transporte básico | D8: Peluquería | H8: julio
A9: agosto 2025 | C9: Seguros | D9: Deporte | H9: agosto
A10: septiembre 2025 | C10: Suscripciones esenciales | D10: Formación | H10: septiembre
A11: octubre 2025 | C11: Factura Luz/Agua/Gas | D11: Reparaciones | H11: octubre
A12: noviembre 2025 | C12: Gym | D12: Supermercado | H12: noviembre
A13: diciembre 2025 | C13: Farmacia | D13: Suscripciones | H13: diciembre
A14: enero 2026 | D14: Gasolina
A15: febrero 2026 | D15: Donacion
A16: marzo 2026
A17: abril 2026
A18: mayo 2026
A19: junio 2026
A20: julio 2026
A21: agosto 2026
A22: septiembre 2026
A23: octubre 2026
A24: noviembre 2026
A25: diciembre 2026
